Traceback (most recent call last):
  File "E:\python\Lib\site-packages\httpx\_transports\default.py", line 72, in map_httpcore_exceptions
    yield
  File "E:\python\Lib\site-packages\httpx\_transports\default.py", line 236, in handle_request
    resp = self._pool.handle_request(req)
           ^^^^^^^^^^^^^^^^^^^^^^^^^^^^^^
  File "E:\python\Lib\site-packages\httpcore\_sync\connection_pool.py", line 256, in handle_request
    raise exc from None
  File "E:\python\Lib\site-packages\httpcore\_sync\connection_pool.py", line 236, in handle_request
    response = connection.handle_request(
               ^^^^^^^^^^^^^^^^^^^^^^^^^^
  File "E:\python\Lib\site-packages\httpcore\_sync\http_proxy.py", line 316, in handle_request
    stream = stream.start_tls(**kwargs)
             ^^^^^^^^^^^^^^^^^^^^^^^^^^
  File "E:\python\Lib\site-packages\httpcore\_sync\http11.py", line 376, in start_tls
    return self._stream.start_tls(ssl_context, server_hostname, timeout)
           ^^^^^^^^^^^^^^^^^^^^^^^^^^^^^^^^^^^^^^^^^^^^^^^^^^^^^^^^^^^^^
  File "E:\python\Lib\site-packages\httpcore\_backends\sync.py", line 154, in start_tls
    with map_exceptions(exc_map):
         ^^^^^^^^^^^^^^^^^^^^^^^
  File "E:\python\Lib\contextlib.py", line 158, in __exit__
    self.gen.throw(value)
  File "E:\python\Lib\site-packages\httpcore\_exceptions.py", line 14, in map_exceptions
    raise to_exc(exc) from exc
httpcore.ConnectError: [WinError 10054] 远程主机强迫关闭了一个现有的连接。

The above exception was the direct cause of the following exception:

Traceback (most recent call last):
  File "C:\Users\zhang\Desktop\crypto\currency_leverage_collection\dataGet\mexc_brackets_fetch.py", line 246, in <module>
    out = main(max_symbols=args.max_symbols)
          ^^^^^^^^^^^^^^^^^^^^^^^^^^^^^^^^^^
  File "C:\Users\zhang\Desktop\crypto\currency_leverage_collection\dataGet\mexc_brackets_fetch.py", line 210, in main
    detail = _fetch_detail_v2()
             ^^^^^^^^^^^^^^^^^^
  File "C:\Users\zhang\Desktop\crypto\currency_leverage_collection\dataGet\mexc_brackets_fetch.py", line 61, in _fetch_detail_v2
    r = client.get(url)
        ^^^^^^^^^^^^^^^
  File "E:\python\Lib\site-packages\httpx\_client.py", line 1066, in get
    return self.request(
           ^^^^^^^^^^^^^
  File "E:\python\Lib\site-packages\httpx\_client.py", line 837, in request
    return self.send(request, auth=auth, follow_redirects=follow_redirects)
           ^^^^^^^^^^^^^^^^^^^^^^^^^^^^^^^^^^^^^^^^^^^^^^^^^^^^^^^^^^^^^^^^
  File "E:\python\Lib\site-packages\httpx\_client.py", line 926, in send
    response = self._send_handling_auth(
               ^^^^^^^^^^^^^^^^^^^^^^^^^
  File "E:\python\Lib\site-packages\httpx\_client.py", line 954, in _send_handling_auth
    response = self._send_handling_redirects(
               ^^^^^^^^^^^^^^^^^^^^^^^^^^^^^^
  File "E:\python\Lib\site-packages\httpx\_client.py", line 991, in _send_handling_redirects
    response = self._send_single_request(request)
               ^^^^^^^^^^^^^^^^^^^^^^^^^^^^^^^^^^
  File "E:\python\Lib\site-packages\httpx\_client.py", line 1027, in _send_single_request
    response = transport.handle_request(request)
               ^^^^^^^^^^^^^^^^^^^^^^^^^^^^^^^^^
  File "E:\python\Lib\site-packages\httpx\_transports\default.py", line 235, in handle_request
    with map_httpcore_exceptions():
         ^^^^^^^^^^^^^^^^^^^^^^^^^
  File "E:\python\Lib\contextlib.py", line 158, in __exit__
    self.gen.throw(value)
  File "E:\python\Lib\site-packages\httpx\_transports\default.py", line 89, in map_httpcore_exceptions
    raise mapped_exc(message) from exc
httpx.ConnectError: [WinError 10054] 远程主机强迫关闭了一个现有的连接。
